Workbook

Sheet README
A1: Baseline Data Use Case Alignment — Day 20 V2
A3: Purpose
A4: One sheet per use case to review required data elements, why each is needed, and outstanding questions. Dynamic counts on the Use Case Index and Data Element Matrix are driven by formulas — do not change them.
A6: Team review rules (audit)
A7: • Do NOT edit formulas, structured fields, or cells outside your comment column.
A8: • Do NOT change another reviewer’s comments.
A9: • Add all feedback only in the column with your name: Kim Comments, Stephanie Comments, or Briana Comments (on each use case tab, before Review Status).
A10: • Use Review Status only when confirming overall status for that data element row.
A12: Navigation
A13: • Use Case Index — Sheet Name links open the matching use case tab.
A14: • Each use case tab row 2 links back to Use Case Index and Data Element Matrix.
A16: Sheets
... A20: • Open Questions — consolidated follow-ups.

Sheet Data Element Matrix
B2: ='Use Case Index'!$B2 | C2: ='Use Case Index'!$B3 | D2: ='Use Case Index'!$B3 | E2: ='Use Case Index'!$B4 | F2: ='Use Case Index'!$B5 | G2: ='Use Case Index'!$B6 | H2: ='Use Case Index'!$B7 | I2: ='Use Case Index'!$B8 | J2: ='Use Case Index'!$B9 | K2: ='Use Case Index'!$B10 | L2: ='Use Case Index'!$B11 | M2: ='Use Case Index'!$B12 | N2: ='Use Case Index'!$B13 | O2: ='Use Case Index'!$B14 | P2: ='Use Case Index'!$B15 | Q2: ='Use Case Index'!$B16 | R2: ='Use Case Index'!$B17 | S2: ='Use Case Index'!$B18 | T2: ='Use Case Index'!$B19 | U2: ='Use Case Index'!$B20 | V2: ='Use Case Index'!$B21 | W2: ='Use Case Index'!$B22 | X2: ='Use Case Index'!$B23 | Y2: ='Use Case Index'!$B24 | Z2: ='Use Case Index'!$B25 | AA2: ='Use Case Index'!$B6 | AB2: ='Use Case Index'!$B27 | AC2: ='Use Case Index'!$B28 | AD2: ='Use Case Index'!$B29 | AE2: ='Use Case Index'!$B30 | AF2: ='Use Case Index'!$B31 | AG2: ='Use Case Index'!$B32
A3: {=_xlfn.LET( _xlpm.RawElements, _xlfn.UNIQUE(_xlfn._xlws.FILTER( _xlfn.VSTACK( 'UC01 Content Syndication Attend'!$A$7:$A$100, 'UC02 Content Syndication Form S'!$A$7:$A$100, 'UC03 Content Syndication Attend'!$A$7:$A$100, 'UC04 Content Syndication Form S'!$A$7:$A$100, 'UC05 1st Party Events Follow-Up'!$A$7:$A$100, 'UC06 3rd Party Events Follow-Up'!$A$7:$A$100 ), (_xlfn.VSTACK( 'UC01 Content Syndication Attend'!$A$7:$A$100, 'UC02 Content Syndication Form S'!$A$7:$A$100, 'UC03 Content Syndication Attend'!$A$7:$A$100, 'UC04 Content Syndication Form S'!$A$7:$A$100, 'UC05 1st Party Events Follow-Up'!$A$7:$A$100, 'UC06 3rd Party Events Follow-Up'!$A$7:$A$100 )<>"") )), _xlpm.DataElementsOnly, _xlfn._xlws.FILTER(_xlpm.RawElements, ISERROR(VALUE(LEFT(_xlpm.RawElements, 1)))), _xlpm.ElementSections, _xlfn.XLOOKUP(_xlpm.DataElementsOnly, 'Ref - Master Schema'!$A:$A, 'Ref - Master Schema'!$B:$B, "Unassigned"), _xlpm.SortedElements, _xlfn.SORTBY(_xlpm.DataElementsOnly, LEFT(_xlpm.ElementSections, 1), 1, _xlpm.DataElementsOnly, 1), _xlpm.SectionsOnly, _xlfn.UNIQUE(_xlfn._xlws.FILTER('Ref - Master Schema'!$B:$B, 'Ref - Master Schema'!$B:$B<>"")), _xlfn.SORTBY(_xlfn.VSTACK(_xlpm.SectionsOnly, _xlpm.DataElementsOnly), LEFT(IFERROR(_xlfn.XLOOKUP(_xlfn.VSTACK(_xlpm.SectionsOnly, _xlpm.DataElementsOnly), 'Ref - Master Schema'!$A:$A, 'Ref - Master Schema'!$B:$B), _xlfn.VSTACK(_xlpm.SectionsOnly, _xlpm.DataElementsOnly)), 1), 1) )} | B3: {=IF( ISNUMBER(VALUE(LEFT($A3, 1))), "", IFERROR(IF(_xlfn.XLOOKUP($A3, INDIRECT("'" & B$2 & "'!$A:$A"), INDIRECT("'" & B$2 & "'!$B:$B"), "")<>"", "✓", "✗"), "✗") )} | C3: {=IF( ISNUMBER(VALUE(LEFT($A3, 1))), "", IFERROR(IF(_xlfn.XLOOKUP($A3, INDIRECT("'" & C$2 & "'!$A:$A"), INDIRECT("'" & C$2 & "'!$B:$B"), "")<>"", "✓", "✗"), "✗") )} | D3: {=IF( ISNUMBER(VALUE(LEFT($A3, 1))), "", IFERROR(IF(_xlfn.XLOOKUP($A3, INDIRECT("'" & D$2 & "'!$A:$A"), INDIRECT("'" & D$2 & "'!$B:$B"), "")<>"", "✓", "✗"), "✗") )} | E3: {=IF( ISNUMBER(VALUE(LEFT($A3, 1))), "", IFERROR(IF(_xlfn.XLOOKUP($A3, INDIRECT("'" & E$2 & "'!$A:$A"), INDIRECT("'" & E$2 & "'!$B:$B"), "")<>"", "✓", "✗"), "✗") )} | F3: {=IF( ISNUMBER(VALUE(LEFT($A3, 1))), "", IFERROR(IF(_xlfn.XLOOKUP($A3, INDIRECT("'" & F$2 & "'!$A:$A"), INDIRECT("'" & F$2 & "'!$B:$B"), "")<>"", "✓", "✗"), "✗") )} | G3: {=IF( ISNUMBER(VALUE(LEFT($A3, 1))), "", IFERROR(IF(_xlfn.XLOOKUP($A3, INDIRECT("'" & G$2 & "'!$A:$A"), INDIRECT("'" & G$2 & "'!$B:$B"), "")<>"", "✓", "✗"), "✗") )} | H3: {=IF( ISNUMBER(VALUE(LEFT($A3, 1))), "", IFERROR(IF(_xlfn.XLOOKUP($A3, INDIRECT("'" & H$2 & "'!$A:$A"), INDIRECT("'" & H$2 & "'!$B:$B"), "")<>"", "✓", "✗"), "✗") )} | I3: {=IF( ISNUMBER(VALUE(LEFT($A3, 1))), "", IFERROR(IF(_xlfn.XLOOKUP($A3, INDIRECT("'" & I$2 & "'!$A:$A"), INDIRECT("'" & I$2 & "'!$B:$B"), "")<>"", "✓", "✗"), "✗") )} | ... AG3: {=IF( ISNUMBER(VALUE(LEFT($A3, 1))), "", IFERROR(IF(_xlfn.XLOOKUP($A3, INDIRECT("'" & AG$2 & "'!$A:$A"), INDIRECT("'" & AG$2 & "'!$B:$B"), "")<>"", "✓", "✗"), "✗") )}
A4: Activity Type | B4: {=IF( ISNUMBER(VALUE(LEFT($A4, 1))), "", IFERROR(IF(_xlfn.XLOOKUP($A4, INDIRECT("'" & B$2 & "'!$A:$A"), INDIRECT("'" & B$2 & "'!$B:$B"), "")<>"", "✓", "✗"), "✗") )} | C4: {=IF( ISNUMBER(VALUE(LEFT($A4, 1))), "", IFERROR(IF(_xlfn.XLOOKUP($A4, INDIRECT("'" & C$2 & "'!$A:$A"), INDIRECT("'" & C$2 & "'!$B:$B"), "")<>"", "✓", "✗"), "✗") )} | D4: {=IF( ISNUMBER(VALUE(LEFT($A4, 1))), "", IFERROR(IF(_xlfn.XLOOKUP($A4, INDIRECT("'" & D$2 & "'!$A:$A"), INDIRECT("'" & D$2 & "'!$B:$B"), "")<>"", "✓", "✗"), "✗") )} | E4: {=IF( ISNUMBER(VALUE(LEFT($A4, 1))), "", IFERROR(IF(_xlfn.XLOOKUP($A4, INDIRECT("'" & E$2 & "'!$A:$A"), INDIRECT("'" & E$2 & "'!$B:$B"), "")<>"", "✓", "✗"), "✗") )} | F4: {=IF( ISNUMBER(VALUE(LEFT($A4, 1))), "", IFERROR(IF(_xlfn.XLOOKUP($A4, INDIRECT("'" & F$2 & "'!$A:$A"), INDIRECT("'" & F$2 & "'!$B:$B"), "")<>"", "✓", "✗"), "✗") )} | G4: {=IF( ISNUMBER(VALUE(LEFT($A4, 1))), "", IFERROR(IF(_xlfn.XLOOKUP($A4, INDIRECT("'" & G$2 & "'!$A:$A"), INDIRECT("'" & G$2 & "'!$B:$B"), "")<>"", "✓", "✗"), "✗") )} | H4: {=IF( ISNUMBER(VALUE(LEFT($A4, 1))), "", IFERROR(IF(_xlfn.XLOOKUP($A4, INDIRECT("'" & H$2 & "'!$A:$A"), INDIRECT("'" & H$2 & "'!$B:$B"), "")<>"", "✓", "✗"), "✗") )} | I4: {=IF( ISNUMBER(VALUE(LEFT($A4, 1))), "", IFERROR(IF(_xlfn.XLOOKUP($A4, INDIRECT("'" & I$2 & "'!$A:$A"), INDIRECT("'" & I$2 & "'!$B:$B"), "")<>"", "✓", "✗"), "✗") )} | ... AG4: {=IF( ISNUMBER(VALUE(LEFT($A4, 1))), "", IFERROR(IF(_xlfn.XLOOKUP($A4, INDIRECT("'" & AG$2 & "'!$A:$A"), INDIRECT("'" & AG$2 & "'!$B:$B"), "")<>"", "✓", "✗"), "✗") )}
A5: Use Case | B5: {=IF( ISNUMBER(VALUE(LEFT($A5, 1))), "", IFERROR(IF(_xlfn.XLOOKUP($A5, INDIRECT("'" & B$2 & "'!$A:$A"), INDIRECT("'" & B$2 & "'!$B:$B"), "")<>"", "✓", "✗"), "✗") )} | C5: {=IF( ISNUMBER(VALUE(LEFT($A5, 1))), "", IFERROR(IF(_xlfn.XLOOKUP($A5, INDIRECT("'" & C$2 & "'!$A:$A"), INDIRECT("'" & C$2 & "'!$B:$B"), "")<>"", "✓", "✗"), "✗") )} | D5: {=IF( ISNUMBER(VALUE(LEFT($A5, 1))), "", IFERROR(IF(_xlfn.XLOOKUP($A5, INDIRECT("'" & D$2 & "'!$A:$A"), INDIRECT("'" & D$2 & "'!$B:$B"), "")<>"", "✓", "✗"), "✗") )} | E5: {=IF( ISNUMBER(VALUE(LEFT($A5, 1))), "", IFERROR(IF(_xlfn.XLOOKUP($A5, INDIRECT("'" & E$2 & "'!$A:$A"), INDIRECT("'" & E$2 & "'!$B:$B"), "")<>"", "✓", "✗"), "✗") )} | F5: {=IF( ISNUMBER(VALUE(LEFT($A5, 1))), "", IFERROR(IF(_xlfn.XLOOKUP($A5, INDIRECT("'" & F$2 & "'!$A:$A"), INDIRECT("'" & F$2 & "'!$B:$B"), "")<>"", "✓", "✗"), "✗") )} | G5: {=IF( ISNUMBER(VALUE(LEFT($A5, 1))), "", IFERROR(IF(_xlfn.XLOOKUP($A5, INDIRECT("'" & G$2 & "'!$A:$A"), INDIRECT("'" & G$2 & "'!$B:$B"), "")<>"", "✓", "✗"), "✗") )} | H5: {=IF( ISNUMBER(VALUE(LEFT($A5, 1))), "", IFERROR(IF(_xlfn.XLOOKUP($A5, INDIRECT("'" & H$2 & "'!$A:$A"), INDIRECT("'" & H$2 & "'!$B:$B"), "")<>"", "✓", "✗"), "✗") )} | I5: {=IF( ISNUMBER(VALUE(LEFT($A5, 1))), "", IFERROR(IF(_xlfn.XLOOKUP($A5, INDIRECT("'" & I$2 & "'!$A:$A"), INDIRECT("'" & I$2 & "'!$B:$B"), "")<>"", "✓", "✗"), "✗") )} | ... AG5: {=IF( ISNUMBER(VALUE(LEFT($A5, 1))), "", IFERROR(IF(_xlfn.XLOOKUP($A5, INDIRECT("'" & AG$2 & "'!$A:$A"), INDIRECT("'" & AG$2 & "'!$B:$B"), "")<>"", "✓", "✗"), "✗") )}
A6: Lead Category | B6: {=IF( ISNUMBER(VALUE(LEFT($A6, 1))), "", IFERROR(IF(_xlfn.XLOOKUP($A6, INDIRECT("'" & B$2 & "'!$A:$A"), INDIRECT("'" & B$2 & "'!$B:$B"), "")<>"", "✓", "✗"), "✗") )} | C6: {=IF( ISNUMBER(VALUE(LEFT($A6, 1))), "", IFERROR(IF(_xlfn.XLOOKUP($A6, INDIRECT("'" & C$2 & "'!$A:$A"), INDIRECT("'" & C$2 & "'!$B:$B"), "")<>"", "✓", "✗"), "✗") )} | D6: {=IF( ISNUMBER(VALUE(LEFT($A6, 1))), "", IFERROR(IF(_xlfn.XLOOKUP($A6, INDIRECT("'" & D$2 & "'!$A:$A"), INDIRECT("'" & D$2 & "'!$B:$B"), "")<>"", "✓", "✗"), "✗") )} | E6: {=IF( ISNUMBER(VALUE(LEFT($A6, 1))), "", IFERROR(IF(_xlfn.XLOOKUP($A6, INDIRECT("'" & E$2 & "'!$A:$A"), INDIRECT("'" & E$2 & "'!$B:$B"), "")<>"", "✓", "✗"), "✗") )} | F6: {=IF( ISNUMBER(VALUE(LEFT($A6, 1))), "", IFERROR(IF(_xlfn.XLOOKUP($A6, INDIRECT("'" & F$2 & "'!$A:$A"), INDIRECT("'" & F$2 & "'!$B:$B"), "")<>"", "✓", "✗"), "✗") )} | G6: {=IF( ISNUMBER(VALUE(LEFT($A6, 1))), "", IFERROR(IF(_xlfn.XLOOKUP($A6, INDIRECT("'" & G$2 & "'!$A:$A"), INDIRECT("'" & G$2 & "'!$B:$B"), "")<>"", "✓", "✗"), "✗") )} | H6: {=IF( ISNUMBER(VALUE(LEFT($A6, 1))), "", IFERROR(IF(_xlfn.XLOOKUP($A6, INDIRECT("'" & H$2 & "'!$A:$A"), INDIRECT("'" & H$2 & "'!$B:$B"), "")<>"", "✓", "✗"), "✗") )} | I6: {=IF( ISNUMBER(VALUE(LEFT($A6, 1))), "", IFERROR(IF(_xlfn.XLOOKUP($A6, INDIRECT("'" & I$2 & "'!$A:$A"), INDIRECT("'" & I$2 & "'!$B:$B"), "")<>"", "✓", "✗"), "✗") )} | ... AG6: {=IF( ISNUMBER(VALUE(LEFT($A6, 1))), "", IFERROR(IF(_xlfn.XLOOKUP($A6, INDIRECT("'" & AG$2 & "'!$A:$A"), INDIRECT("'" & AG$2 & "'!$B:$B"), "")<>"", "✓", "✗"), "✗") )}
A7: Sales Routing Trigger | B7: {=IF( ISNUMBER(VALUE(LEFT($A7, 1))), "", IFERROR(IF(_xlfn.XLOOKUP($A7, INDIRECT("'" & B$2 & "'!$A:$A"), INDIRECT("'" & B$2 & "'!$B:$B"), "")<>"", "✓", "✗"), "✗") )} | C7: {=IF( ISNUMBER(VALUE(LEFT($A7, 1))), "", IFERROR(IF(_xlfn.XLOOKUP($A7, INDIRECT("'" & C$2 & "'!$A:$A"), INDIRECT("'" & C$2 & "'!$B:$B"), "")<>"", "✓", "✗"), "✗") )} | D7: {=IF( ISNUMBER(VALUE(LEFT($A7, 1))), "", IFERROR(IF(_xlfn.XLOOKUP($A7, INDIRECT("'" & D$2 & "'!$A:$A"), INDIRECT("'" & D$2 & "'!$B:$B"), "")<>"", "✓", "✗"), "✗") )} | E7: {=IF( ISNUMBER(VALUE(LEFT($A7, 1))), "", IFERROR(IF(_xlfn.XLOOKUP($A7, INDIRECT("'" & E$2 & "'!$A:$A"), INDIRECT("'" & E$2 & "'!$B:$B"), "")<>"", "✓", "✗"), "✗") )} | F7: {=IF( ISNUMBER(VALUE(LEFT($A7, 1))), "", IFERROR(IF(_xlfn.XLOOKUP($A7, INDIRECT("'" & F$2 & "'!$A:$A"), INDIRECT("'" & F$2 & "'!$B:$B"), "")<>"", "✓", "✗"), "✗") )} | G7: {=IF( ISNUMBER(VALUE(LEFT($A7, 1))), "", IFERROR(IF(_xlfn.XLOOKUP($A7, INDIRECT("'" & G$2 & "'!$A:$A"), INDIRECT("'" & G$2 & "'!$B:$B"), "")<>"", "✓", "✗"), "✗") )} | H7: {=IF( ISNUMBER(VALUE(LEFT($A7, 1))), "", IFERROR(IF(_xlfn.XLOOKUP($A7, INDIRECT("'" & H$2 & "'!$A:$A"), INDIRECT("'" & H$2 & "'!$B:$B"), "")<>"", "✓", "✗"), "✗") )} | I7: {=IF( ISNUMBER(VALUE(LEFT($A7, 1))), "", IFERROR(IF(_xlfn.XLOOKUP($A7, INDIRECT("'" & I$2 & "'!$A:$A"), INDIRECT("'" & I$2 & "'!$B:$B"), "")<>"", "✓", "✗"), "✗") )} | ... AG7: {=IF( ISNUMBER(VALUE(LEFT($A7, 1))), "", IFERROR(IF(_xlfn.XLOOKUP($A7, INDIRECT("'" & AG$2 & "'!$A:$A"), INDIRECT("'" & AG$2 & "'!$B:$B"), "")<>"", "✓", "✗"), "✗") )}
A8: 2 - Contact Identity | B8: {=IF( ISNUMBER(VALUE(LEFT($A8, 1))), "", IFERROR(IF(_xlfn.XLOOKUP($A8, INDIRECT("'" & B$2 & "'!$A:$A"), INDIRECT("'" & B$2 & "'!$B:$B"), "")<>"", "✓", "✗"), "✗") )} | C8: {=IF( ISNUMBER(VALUE(LEFT($A8, 1))), "", IFERROR(IF(_xlfn.XLOOKUP($A8, INDIRECT("'" & C$2 & "'!$A:$A"), INDIRECT("'" & C$2 & "'!$B:$B"), "")<>"", "✓", "✗"), "✗") )} | D8: {=IF( ISNUMBER(VALUE(LEFT($A8, 1))), "", IFERROR(IF(_xlfn.XLOOKUP($A8, INDIRECT("'" & D$2 & "'!$A:$A"), INDIRECT("'" & D$2 & "'!$B:$B"), "")<>"", "✓", "✗"), "✗") )} | E8: {=IF( ISNUMBER(VALUE(LEFT($A8, 1))), "", IFERROR(IF(_xlfn.XLOOKUP($A8, INDIRECT("'" & E$2 & "'!$A:$A"), INDIRECT("'" & E$2 & "'!$B:$B"), "")<>"", "✓", "✗"), "✗") )} | F8: {=IF( ISNUMBER(VALUE(LEFT($A8, 1))), "", IFERROR(IF(_xlfn.XLOOKUP($A8, INDIRECT("'" & F$2 & "'!$A:$A"), INDIRECT("'" & F$2 & "'!$B:$B"), "")<>"", "✓", "✗"), "✗") )} | G8: {=IF( ISNUMBER(VALUE(LEFT($A8, 1))), "", IFERROR(IF(_xlfn.XLOOKUP($A8, INDIRECT("'" & G$2 & "'!$A:$A"), INDIRECT("'" & G$2 & "'!$B:$B"), "")<>"", "✓", "✗"), "✗") )} | H8: {=IF( ISNUMBER(VALUE(LEFT($A8, 1))), "", IFERROR(IF(_xlfn.XLOOKUP($A8, INDIRECT("'" & H$2 & "'!$A:$A"), INDIRECT("'" & H$2 & "'!$B:$B"), "")<>"", "✓", "✗"), "✗") )} | I8: {=IF( ISNUMBER(VALUE(LEFT($A8, 1))), "", IFERROR(IF(_xlfn.XLOOKUP($A8, INDIRECT("'" & I$2 & "'!$A:$A"), INDIRECT("'" & I$2 & "'!$B:$B"), "")<>"", "✓", "✗"), "✗") )} | ... AG8: {=IF( ISNUMBER(VALUE(LEFT($A8, 1))), "", IFERROR(IF(_xlfn.XLOOKUP($A8, INDIRECT("'" & AG$2 & "'!$A:$A"), INDIRECT("'" & AG$2 & "'!$B:$B"), "")<>"", "✓", "✗"), "✗") )}
A9: Person Party ID | B9: {=IF( ISNUMBER(VALUE(LEFT($A9, 1))), "", IFERROR(IF(_xlfn.XLOOKUP($A9, INDIRECT("'" & B$2 & "'!$A:$A"), INDIRECT("'" & B$2 & "'!$B:$B"), "")<>"", "✓", "✗"), "✗") )} | C9: {=IF( ISNUMBER(VALUE(LEFT($A9, 1))), "", IFERROR(IF(_xlfn.XLOOKUP($A9, INDIRECT("'" & C$2 & "'!$A:$A"), INDIRECT("'" & C$2 & "'!$B:$B"), "")<>"", "✓", "✗"), "✗") )} | D9: {=IF( ISNUMBER(VALUE(LEFT($A9, 1))), "", IFERROR(IF(_xlfn.XLOOKUP($A9, INDIRECT("'" & D$2 & "'!$A:$A"), INDIRECT("'" & D$2 & "'!$B:$B"), "")<>"", "✓", "✗"), "✗") )} | E9: {=IF( ISNUMBER(VALUE(LEFT($A9, 1))), "", IFERROR(IF(_xlfn.XLOOKUP($A9, INDIRECT("'" & E$2 & "'!$A:$A"), INDIRECT("'" & E$2 & "'!$B:$B"), "")<>"", "✓", "✗"), "✗") )} | F9: {=IF( ISNUMBER(VALUE(LEFT($A9, 1))), "", IFERROR(IF(_xlfn.XLOOKUP($A9, INDIRECT("'" & F$2 & "'!$A:$A"), INDIRECT("'" & F$2 & "'!$B:$B"), "")<>"", "✓", "✗"), "✗") )} | G9: {=IF( ISNUMBER(VALUE(LEFT($A9, 1))), "", IFERROR(IF(_xlfn.XLOOKUP($A9, INDIRECT("'" & G$2 & "'!$A:$A"), INDIRECT("'" & G$2 & "'!$B:$B"), "")<>"", "✓", "✗"), "✗") )} | H9: {=IF( ISNUMBER(VALUE(LEFT($A9, 1))), "", IFERROR(IF(_xlfn.XLOOKUP($A9, INDIRECT("'" & H$2 & "'!$A:$A"), INDIRECT("'" & H$2 & "'!$B:$B"), "")<>"", "✓", "✗"), "✗") )} | I9: {=IF( ISNUMBER(VALUE(LEFT($A9, 1))), "", IFERROR(IF(_xlfn.XLOOKUP($A9, INDIRECT("'" & I$2 & "'!$A:$A"), INDIRECT("'" & I$2 & "'!$B:$B"), "")<>"", "✓", "✗"), "✗") )} | ... AG9: {=IF( ISNUMBER(VALUE(LEFT($A9, 1))), "", IFERROR(IF(_xlfn.XLOOKUP($A9, INDIRECT("'" & AG$2 & "'!$A:$A"), INDIRECT("'" & AG$2 & "'!$B:$B"), "")<>"", "✓", "✗"), "✗") )}
A10: UUID | B10: {=IF( ISNUMBER(VALUE(LEFT($A10, 1))), "", IFERROR(IF(_xlfn.XLOOKUP($A10, INDIRECT("'" & B$2 & "'!$A:$A"), INDIRECT("'" & B$2 & "'!$B:$B"), "")<>"", "✓", "✗"), "✗") )} | C10: {=IF( ISNUMBER(VALUE(LEFT($A10, 1))), "", IFERROR(IF(_xlfn.XLOOKUP($A10, INDIRECT("'" & C$2 & "'!$A:$A"), INDIRECT("'" & C$2 & "'!$B:$B"), "")<>"", "✓", "✗"), "✗") )} | D10: {=IF( ISNUMBER(VALUE(LEFT($A10, 1))), "", IFERROR(IF(_xlfn.XLOOKUP($A10, INDIRECT("'" & D$2 & "'!$A:$A"), INDIRECT("'" & D$2 & "'!$B:$B"), "")<>"", "✓", "✗"), "✗") )} | E10: {=IF( ISNUMBER(VALUE(LEFT($A10, 1))), "", IFERROR(IF(_xlfn.XLOOKUP($A10, INDIRECT("'" & E$2 & "'!$A:$A"), INDIRECT("'" & E$2 & "'!$B:$B"), "")<>"", "✓", "✗"), "✗") )} | F10: {=IF( ISNUMBER(VALUE(LEFT($A10, 1))), "", IFERROR(IF(_xlfn.XLOOKUP($A10, INDIRECT("'" & F$2 & "'!$A:$A"), INDIRECT("'" & F$2 & "'!$B:$B"), "")<>"", "✓", "✗"), "✗") )} | G10: {=IF( ISNUMBER(VALUE(LEFT($A10, 1))), "", IFERROR(IF(_xlfn.XLOOKUP($A10, INDIRECT("'" & G$2 & "'!$A:$A"), INDIRECT("'" & G$2 & "'!$B:$B"), "")<>"", "✓", "✗"), "✗") )} | H10: {=IF( ISNUMBER(VALUE(LEFT($A10, 1))), "", IFERROR(IF(_xlfn.XLOOKUP($A10, INDIRECT("'" & H$2 & "'!$A:$A"), INDIRECT("'" & H$2 & "'!$B:$B"), "")<>"", "✓", "✗"), "✗") )} | I10: {=IF( ISNUMBER(VALUE(LEFT($A10, 1))), "", IFERROR(IF(_xlfn.XLOOKUP($A10, INDIRECT("'" & I$2 & "'!$A:$A"), INDIRECT("'" & I$2 & "'!$B:$B"), "")<>"", "✓", "✗"), "✗") )} | ... AG10: {=IF( ISNUMBER(VALUE(LEFT($A10, 1))), "", IFERROR(IF(_xlfn.XLOOKUP($A10, INDIRECT("'" & AG$2 & "'!$A:$A"), INDIRECT("'" & AG$2 & "'!$B:$B"), "")<>"", "✓", "✗"), "✗") )}
A11: Marketing Automation Tool Contact ID | B11: {=IF( ISNUMBER(VALUE(LEFT($A11, 1))), "", IFERROR(IF(_xlfn.XLOOKUP($A11, INDIRECT("'" & B$2 & "'!$A:$A"), INDIRECT("'" & B$2 & "'!$B:$B"), "")<>"", "✓", "✗"), "✗") )} | C11: {=IF( ISNUMBER(VALUE(LEFT($A11, 1))), "", IFERROR(IF(_xlfn.XLOOKUP($A11, INDIRECT("'" & C$2 & "'!$A:$A"), INDIRECT("'" & C$2 & "'!$B:$B"), "")<>"", "✓", "✗"), "✗") )} | D11: {=IF( ISNUMBER(VALUE(LEFT($A11, 1))), "", IFERROR(IF(_xlfn.XLOOKUP($A11, INDIRECT("'" & D$2 & "'!$A:$A"), INDIRECT("'" & D$2 & "'!$B:$B"), "")<>"", "✓", "✗"), "✗") )} | E11: {=IF( ISNUMBER(VALUE(LEFT($A11, 1))), "", IFERROR(IF(_xlfn.XLOOKUP($A11, INDIRECT("'" & E$2 & "'!$A:$A"), INDIRECT("'" & E$2 & "'!$B:$B"), "")<>"", "✓", "✗"), "✗") )} | F11: {=IF( ISNUMBER(VALUE(LEFT($A11, 1))), "", IFERROR(IF(_xlfn.XLOOKUP($A11, INDIRECT("'" & F$2 & "'!$A:$A"), INDIRECT("'" & F$2 & "'!$B:$B"), "")<>"", "✓", "✗"), "✗") )} | G11: {=IF( ISNUMBER(VALUE(LEFT($A11, 1))), "", IFERROR(IF(_xlfn.XLOOKUP($A11, INDIRECT("'" & G$2 & "'!$A:$A"), INDIRECT("'" & G$2 & "'!$B:$B"), "")<>"", "✓", "✗"), "✗") )} | H11: {=IF( ISNUMBER(VALUE(LEFT($A11, 1))), "", IFERROR(IF(_xlfn.XLOOKUP($A11, INDIRECT("'" & H$2 & "'!$A:$A"), INDIRECT("'" & H$2 & "'!$B:$B"), "")<>"", "✓", "✗"), "✗") )} | I11: {=IF( ISNUMBER(VALUE(LEFT($A11, 1))), "", IFERROR(IF(_xlfn.XLOOKUP($A11, INDIRECT("'" & I$2 & "'!$A:$A"), INDIRECT("'" & I$2 & "'!$B:$B"), "")<>"", "✓", "✗"), "✗") )} | ... AG11: {=IF( ISNUMBER(VALUE(LEFT($A11, 1))), "", IFERROR(IF(_xlfn.XLOOKUP($A11, INDIRECT("'" & AG$2 & "'!$A:$A"), INDIRECT("'" & AG$2 & "'!$B:$B"), "")<>"", "✓", "✗"), "✗") )}
A12: First Name | B12: {=IF( ISNUMBER(VALUE(LEFT($A12, 1))), "", IFERROR(IF(_xlfn.XLOOKUP($A12, INDIRECT("'" & B$2 & "'!$A:$A"), INDIRECT("'" & B$2 & "'!$B:$B"), "")<>"", "✓", "✗"), "✗") )} | C12: {=IF( ISNUMBER(VALUE(LEFT($A12, 1))), "", IFERROR(IF(_xlfn.XLOOKUP($A12, INDIRECT("'" & C$2 & "'!$A:$A"), INDIRECT("'" & C$2 & "'!$B:$B"), "")<>"", "✓", "✗"), "✗") )} | D12: {=IF( ISNUMBER(VALUE(LEFT($A12, 1))), "", IFERROR(IF(_xlfn.XLOOKUP($A12, INDIRECT("'" & D$2 & "'!$A:$A"), INDIRECT("'" & D$2 & "'!$B:$B"), "")<>"", "✓", "✗"), "✗") )} | E12: {=IF( ISNUMBER(VALUE(LEFT($A12, 1))), "", IFERROR(IF(_xlfn.XLOOKUP($A12, INDIRECT("'" & E$2 & "'!$A:$A"), INDIRECT("'" & E$2 & "'!$B:$B"), "")<>"", "✓", "✗"), "✗") )} | F12: {=IF( ISNUMBER(VALUE(LEFT($A12, 1))), "", IFERROR(IF(_xlfn.XLOOKUP($A12, INDIRECT("'" & F$2 & "'!$A:$A"), INDIRECT("'" & F$2 & "'!$B:$B"), "")<>"", "✓", "✗"), "✗") )} | G12: {=IF( ISNUMBER(VALUE(LEFT($A12, 1))), "", IFERROR(IF(_xlfn.XLOOKUP($A12, INDIRECT("'" & G$2 & "'!$A:$A"), INDIRECT("'" & G$2 & "'!$B:$B"), "")<>"", "✓", "✗"), "✗") )} | H12: {=IF( ISNUMBER(VALUE(LEFT($A12, 1))), "", IFERROR(IF(_xlfn.XLOOKUP($A12, INDIRECT("'" & H$2 & "'!$A:$A"), INDIRECT("'" & H$2 & "'!$B:$B"), "")<>"", "✓", "✗"), "✗") )} | I12: {=IF( ISNUMBER(VALUE(LEFT($A12, 1))), "", IFERROR(IF(_xlfn.XLOOKUP($A12, INDIRECT("'" & I$2 & "'!$A:$A"), INDIRECT("'" & I$2 & "'!$B:$B"), "")<>"", "✓", "✗"), "✗") )} | ... AG12: {=IF( ISNUMBER(VALUE(LEFT($A12, 1))), "", IFERROR(IF(_xlfn.XLOOKUP($A12, INDIRECT("'" & AG$2 & "'!$A:$A"), INDIRECT("'" & AG$2 & "'!$B:$B"), "")<>"", "✓", "✗"), "✗") )}
A13: Last Name | B13: {=IF( ISNUMBER(VALUE(LEFT($A13, 1))), "", IFERROR(IF(_xlfn.XLOOKUP($A13, INDIRECT("'" & B$2 & "'!$A:$A"), INDIRECT("'" & B$2 & "'!$B:$B"), "")<>"", "✓", "✗"), "✗") )} | C13: {=IF( ISNUMBER(VALUE(LEFT($A13, 1))), "", IFERROR(IF(_xlfn.XLOOKUP($A13, INDIRECT("'" & C$2 & "'!$A:$A"), INDIRECT("'" & C$2 & "'!$B:$B"), "")<>"", "✓", "✗"), "✗") )} | D13: {=IF( ISNUMBER(VALUE(LEFT($A13, 1))), "", IFERROR(IF(_xlfn.XLOOKUP($A13, INDIRECT("'" & D$2 & "'!$A:$A"), INDIRECT("'" & D$2 & "'!$B:$B"), "")<>"", "✓", "✗"), "✗") )} | E13: {=IF( ISNUMBER(VALUE(LEFT($A13, 1))), "", IFERROR(IF(_xlfn.XLOOKUP($A13, INDIRECT("'" & E$2 & "'!$A:$A"), INDIRECT("'" & E$2 & "'!$B:$B"), "")<>"", "✓", "✗"), "✗") )} | F13: {=IF( ISNUMBER(VALUE(LEFT($A13, 1))), "", IFERROR(IF(_xlfn.XLOOKUP($A13, INDIRECT("'" & F$2 & "'!$A:$A"), INDIRECT("'" & F$2 & "'!$B:$B"), "")<>"", "✓", "✗"), "✗") )} | G13: {=IF( ISNUMBER(VALUE(LEFT($A13, 1))), "", IFERROR(IF(_xlfn.XLOOKUP($A13, INDIRECT("'" & G$2 & "'!$A:$A"), INDIRECT("'" & G$2 & "'!$B:$B"), "")<>"", "✓", "✗"), "✗") )} | H13: {=IF( ISNUMBER(VALUE(LEFT($A13, 1))), "", IFERROR(IF(_xlfn.XLOOKUP($A13, INDIRECT("'" & H$2 & "'!$A:$A"), INDIRECT("'" & H$2 & "'!$B:$B"), "")<>"", "✓", "✗"), "✗") )} | I13: {=IF( ISNUMBER(VALUE(LEFT($A13, 1))), "", IFERROR(IF(_xlfn.XLOOKUP($A13, INDIRECT("'" & I$2 & "'!$A:$A"), INDIRECT("'" & I$2 & "'!$B:$B"), "")<>"", "✓", "✗"), "✗") )} | ... AG13: {=IF( ISNUMBER(VALUE(LEFT($A13, 1))), "", IFERROR(IF(_xlfn.XLOOKUP($A13, INDIRECT("'" & AG$2 & "'!$A:$A"), INDIRECT("'" & AG$2 & "'!$B:$B"), "")<>"", "✓", "✗"), "✗") )}
A14: Job Title | B14: {=IF( ISNUMBER(VALUE(LEFT($A14, 1))), "", IFERROR(IF(_xlfn.XLOOKUP($A14, INDIRECT("'" & B$2 & "'!$A:$A"), INDIRECT("'" & B$2 & "'!$B:$B"), "")<>"", "✓", "✗"), "✗") )} | C14: {=IF( ISNUMBER(VALUE(LEFT($A14, 1))), "", IFERROR(IF(_xlfn.XLOOKUP($A14, INDIRECT("'" & C$2 & "'!$A:$A"), INDIRECT("'" & C$2 & "'!$B:$B"), "")<>"", "✓", "✗"), "✗") )} | D14: {=IF( ISNUMBER(VALUE(LEFT($A14, 1))), "", IFERROR(IF(_xlfn.XLOOKUP($A14, INDIRECT("'" & D$2 & "'!$A:$A"), INDIRECT("'" & D$2 & "'!$B:$B"), "")<>"", "✓", "✗"), "✗") )} | E14: {=IF( ISNUMBER(VALUE(LEFT($A14, 1))), "", IFERROR(IF(_xlfn.XLOOKUP($A14, INDIRECT("'" & E$2 & "'!$A:$A"), INDIRECT("'" & E$2 & "'!$B:$B"), "")<>"", "✓", "✗"), "✗") )} | F14: {=IF( ISNUMBER(VALUE(LEFT($A14, 1))), "", IFERROR(IF(_xlfn.XLOOKUP($A14, INDIRECT("'" & F$2 & "'!$A:$A"), INDIRECT("'" & F$2 & "'!$B:$B"), "")<>"", "✓", "✗"), "✗") )} | G14: {=IF( ISNUMBER(VALUE(LEFT($A14, 1))), "", IFERROR(IF(_xlfn.XLOOKUP($A14, INDIRECT("'" & G$2 & "'!$A:$A"), INDIRECT("'" & G$2 & "'!$B:$B"), "")<>"", "✓", "✗"), "✗") )} | H14: {=IF( ISNUMBER(VALUE(LEFT($A14, 1))), "", IFERROR(IF(_xlfn.XLOOKUP($A14, INDIRECT("'" & H$2 & "'!$A:$A"), INDIRECT("'" & H$2 & "'!$B:$B"), "")<>"", "✓", "✗"), "✗") )} | I14: {=IF( ISNUMBER(VALUE(LEFT($A14, 1))), "", IFERROR(IF(_xlfn.XLOOKUP($A14, INDIRECT("'" & I$2 & "'!$A:$A"), INDIRECT("'" & I$2 & "'!$B:$B"), "")<>"", "✓", "✗"), "✗") )} | ... AG14: {=IF( ISNUMBER(VALUE(LEFT($A14, 1))), "", IFERROR(IF(_xlfn.XLOOKUP($A14, INDIRECT("'" & AG$2 & "'!$A:$A"), INDIRECT("'" & AG$2 & "'!$B:$B"), "")<>"", "✓", "✗"), "✗") )}
A15: Job Level | B15: {=IF( ISNUMBER(VALUE(LEFT($A15, 1))), "", IFERROR(IF(_xlfn.XLOOKUP($A15, INDIRECT("'" & B$2 & "'!$A:$A"), INDIRECT("'" & B$2 & "'!$B:$B"), "")<>"", "✓", "✗"), "✗") )} | C15: {=IF( ISNUMBER(VALUE(LEFT($A15, 1))), "", IFERROR(IF(_xlfn.XLOOKUP($A15, INDIRECT("'" & C$2 & "'!$A:$A"), INDIRECT("'" & C$2 & "'!$B:$B"), "")<>"", "✓", "✗"), "✗") )} | D15: {=IF( ISNUMBER(VALUE(LEFT($A15, 1))), "", IFERROR(IF(_xlfn.XLOOKUP($A15, INDIRECT("'" & D$2 & "'!$A:$A"), INDIRECT("'" & D$2 & "'!$B:$B"), "")<>"", "✓", "✗"), "✗") )} | E15: {=IF( ISNUMBER(VALUE(LEFT($A15, 1))), "", IFERROR(IF(_xlfn.XLOOKUP($A15, INDIRECT("'" & E$2 & "'!$A:$A"), INDIRECT("'" & E$2 & "'!$B:$B"), "")<>"", "✓", "✗"), "✗") )} | F15: {=IF( ISNUMBER(VALUE(LEFT($A15, 1))), "", IFERROR(IF(_xlfn.XLOOKUP($A15, INDIRECT("'" & F$2 & "'!$A:$A"), INDIRECT("'" & F$2 & "'!$B:$B"), "")<>"", "✓", "✗"), "✗") )} | G15: {=IF( ISNUMBER(VALUE(LEFT($A15, 1))), "", IFERROR(IF(_xlfn.XLOOKUP($A15, INDIRECT("'" & G$2 & "'!$A:$A"), INDIRECT("'" & G$2 & "'!$B:$B"), "")<>"", "✓", "✗"), "✗") )} | H15: {=IF( ISNUMBER(VALUE(LEFT($A15, 1))), "", IFERROR(IF(_xlfn.XLOOKUP($A15, INDIRECT("'" & H$2 & "'!$A:$A"), INDIRECT("'" & H$2 & "'!$B:$B"), "")<>"", "✓", "✗"), "✗") )} | I15: {=IF( ISNUMBER(VALUE(LEFT($A15, 1))), "", IFERROR(IF(_xlfn.XLOOKUP($A15, INDIRECT("'" & I$2 & "'!$A:$A"), INDIRECT("'" & I$2 & "'!$B:$B"), "")<>"", "✓", "✗"), "✗") )} | ... AG15: {=IF( ISNUMBER(VALUE(LEFT($A15, 1))), "", IFERROR(IF(_xlfn.XLOOKUP($A15, INDIRECT("'" & AG$2 & "'!$A:$A"), INDIRECT("'" & AG$2 & "'!$B:$B"), "")<>"", "✓", "✗"), "✗") )}
... A91: Category | B91: {=IF( ISNUMBER(VALUE(LEFT($A91, 1))), "", IFERROR(IF(_xlfn.XLOOKUP($A91, INDIRECT("'" & B$2 & "'!$A:$A"), INDIRECT("'" & B$2 & "'!$B:$B"), "")<>"", "✓", "✗"), "✗") )} | C91: {=IF( ISNUMBER(VALUE(LEFT($A91, 1))), "", IFERROR(IF(_xlfn.XLOOKUP($A91, INDIRECT("'" & C$2 & "'!$A:$A"), INDIRECT("'" & C$2 & "'!$B:$B"), "")<>"", "✓", "✗"), "✗") )} | D91: {=IF( ISNUMBER(VALUE(LEFT($A91, 1))), "", IFERROR(IF(_xlfn.XLOOKUP($A91, INDIRECT("'" & D$2 & "'!$A:$A"), INDIRECT("'" & D$2 & "'!$B:$B"), "")<>"", "✓", "✗"), "✗") )} | E91: {=IF( ISNUMBER(VALUE(LEFT($A91, 1))), "", IFERROR(IF(_xlfn.XLOOKUP($A91, INDIRECT("'" & E$2 & "'!$A:$A"), INDIRECT("'" & E$2 & "'!$B:$B"), "")<>"", "✓", "✗"), "✗") )} | F91: {=IF( ISNUMBER(VALUE(LEFT($A91, 1))), "", IFERROR(IF(_xlfn.XLOOKUP($A91, INDIRECT("'" & F$2 & "'!$A:$A"), INDIRECT("'" & F$2 & "'!$B:$B"), "")<>"", "✓", "✗"), "✗") )} | G91: {=IF( ISNUMBER(VALUE(LEFT($A91, 1))), "", IFERROR(IF(_xlfn.XLOOKUP($A91, INDIRECT("'" & G$2 & "'!$A:$A"), INDIRECT("'" & G$2 & "'!$B:$B"), "")<>"", "✓", "✗"), "✗") )} | H91: {=IF( ISNUMBER(VALUE(LEFT($A91, 1))), "", IFERROR(IF(_xlfn.XLOOKUP($A91, INDIRECT("'" & H$2 & "'!$A:$A"), INDIRECT("'" & H$2 & "'!$B:$B"), "")<>"", "✓", "✗"), "✗") )} | I91: {=IF( ISNUMBER(VALUE(LEFT($A91, 1))), "", IFERROR(IF(_xlfn.XLOOKUP($A91, INDIRECT("'" & I$2 & "'!$A:$A"), INDIRECT("'" & I$2 & "'!$B:$B"), "")<>"", "✓", "✗"), "✗") )} | ... AG91: {=IF( ISNUMBER(VALUE(LEFT($A91, 1))), "", IFERROR(IF(_xlfn.XLOOKUP($A91, INDIRECT("'" & AG$2 & "'!$A:$A"), INDIRECT("'" & AG$2 & "'!$B:$B"), "")<>"", "✓", "✗"), "✗") )}
B158: =COUNTIF(B$3:B$157, "✓") | C158: =COUNTIF(C$3:C$157, "✓") | D158: =COUNTIF(D$3:D$157, "✓") | E158: =COUNTIF(E$3:E$157, "✓") | F158: =COUNTIF(F$3:F$157, "✓") | G158: =COUNTIF(G$3:G$157, "✓") | H158: =COUNTIF(H$3:H$157, "✓") | I158: =COUNTIF(I$3:I$157, "✓") | ... AD158: =COUNTIF(AD$3:AD$157, "✓")

Sheet Ref - Master Schema
A1: Data Element | B1: Category | F1: Category | I1: ✓
A2: {=_xlfn.LET( _xlpm.RawData, _xlfn.VSTACK( 'UC01 Content Syndication Attend'!$A$7:$A$100, 'UC02 Content Syndication Form S'!$A$7:$A$100, 'UC03 Content Syndication Attend'!$A$7:$A$100, 'UC04 Content Syndication Form S'!$A$7:$A$100, 'UC05 1st Party Events Follow-Up'!$A$7:$A$100, 'UC06 3rd Party Events Follow-Up'!$A$7:$A$100, 'UC07 Paid Leads Follow-Up Reque'!$A$7:$A$100, 'UC08 Webinars Follow-Up Request'!$A$7:$A$100, 'UC09 1st Party Events Attended '!$A$7:$A$100, 'UC10 1st Party Events Attended '!$A$7:$A$100, 'UC11 1st Party Events Attended '!$A$7:$A$100, 'UC12 1st Party Events Booth Sca'!$A$7:$A$100, 'UC13 1st Party Events Registere'!$A$7:$A$100, 'UC14 3rd Party Events Attended '!$A$7:$A$100, 'UC15 3rd Party Events Attended '!$A$7:$A$100, 'UC16 3rd Party Events Attended '!$A$7:$A$100, 'UC17 3rd Party Events Booth Sca'!$A$7:$A$100, 'UC18 3rd Party Events Contact R'!$A$7:$A$100, 'UC19 Event Sponsorships Attende'!$A$7:$A$100, 'UC20 Event Sponsorships Attende'!$A$7:$A$100, 'UC21 Event Sponsorships Registe'!$A$7:$A$100, 'UC22 Webinars Attended Live Vir'!$A$7:$A$100, 'UC23 Webinars Attended On-Deman'!$A$7:$A$100, 'UC24 Webinars Registered'!$A$7:$A$100, 'UC25 Offers - Contact Us Form S'!$A$7:$A$100, 'UC26 Offers - Demo Form Submit'!$A$7:$A$100, 'UC27 Offers - Offer Form Submit'!$A$7:$A$100, 'UC28 Offers - Other Form Submit'!$A$7:$A$100, 'UC29 Offers - Others Form Submi'!$A$7:$A$100, 'UC30 Offers - Promotion Form Su'!$A$7:$A$100, 'UC31 Offers - Trial Form Submit'!$A$7:$A$100, 'UC32 Offers - Trials Form Submi'!$A$7:$A$100 ), _xlpm.CleanData, _xlfn._xlws.FILTER(_xlpm.RawData, (_xlpm.RawData<>"") * (_xlpm.RawData<>0) * (_xlpm.RawData<>"Data Element")), _xlpm.MappedSections, _xlfn.SCAN("", _xlpm.CleanData, _xlfn.LAMBDA(_xlpm.prev,_xlpm.curr, IF(ISNUMBER(VALUE(LEFT(_xlpm.curr, 1))), _xlpm.curr, _xlpm.prev) )), _xlpm.CombinedGrid, _xlfn.HSTACK(_xlpm.CleanData, _xlpm.MappedSections), _xlpm.FinalOutput, _xlfn._xlws.FILTER(_xlpm.CombinedGrid, ISERROR(VALUE(LEFT(INDEX(_xlpm.CombinedGrid, , 1), 1)))), _xlfn.UNIQUE(_xlpm.FinalOutput) )} | B2: 1 - System Classification | F2: 1 - System Classification | I2: ✗
A3: Use Case | B3: 1 - System Classification | F3: 2 - Contact Identity
A4: Lead Category | B4: 1 - System Classification | F4: 3 - Account Identity
A5: Sales Routing Trigger | B5: 1 - System Classification | F5: 4 - Compliance / Permissions
A6: Person Party ID | B6: 2 - Contact Identity | F6: 5 - Legacy Tracking Parameters
A7: UUID | B7: 2 - Contact Identity | F7: 6 - Future Tracking Parameters
A8: Marketing Automation Tool Contact ID | B8: 2 - Contact Identity | F8: 7 - Event Tracking Parameters
A9: First Name | B9: 2 - Contact Identity | F9: 8 - Activity Detail
A10: Last Name | B10: 2 - Contact Identity
A11: Job Title | B11: 2 - Contact Identity
A12: Job Level | B12: 2 - Contact Identity
A13: Job Department | B13: 2 - Contact Identity
A14: Email | B14: 2 - Contact Identity
A15: Email Status | B15: 2 - Contact Identity
A16: OK to Email | B16: 2 - Contact Identity
A17: Phone Status | B17: 2 - Contact Identity
A18: OK to Call | B18: 2 - Contact Identity
A19: Partner Flag | B19: 2 - Contact Identity
A20: Student Flag | B20: 2 - Contact Identity
A21: Decision Maker Type | B21: 2 - Contact Identity
... A123: Marketing Automation Tool Landing Page ID | B123: 8 - Activity Detail

Sheet Use Case Index
A1: Use Case ID | B1: Sheet Name | C1: Process | D1: Lead Category | E1: Use Case | F1: Activity Type | G1: Data Element Count | H1: Open Questions Count
A2: UC01 | B2: {=_xlfn.TEXTAFTER(CELL("filename", 'UC01 Content Syndication Attend'!$A$1), "]")} | C2: Content Syndication | D2: Hand Raiser | E2: Content Syndication | F2: Attended on Demand | G2: =COUNTIF(OFFSET('Data Element Matrix'!$B$4:$B$520, 0, ROW() - 2), "✓") | H2: 6
A3: UC02 | B3: {=_xlfn.TEXTAFTER(CELL("filename", 'UC02 Content Syndication Form S'!$A$1), "]")} | C3: Content Syndication | D3: Hand Raiser | E3: Content Syndication | F3: Form Submit | G3: =COUNTIF(OFFSET('Data Element Matrix'!$B$4:$B$520, 0, ROW() - 2), "✓") | H3: 6
A4: UC03 | B4: {=_xlfn.TEXTAFTER(CELL("filename", 'UC03 Content Syndication Attend'!$A$1), "]")} | C4: Content Syndication | D4: Non-Hand Raiser | E4: Content Syndication | F4: Attended on Demand | G4: =COUNTIF(OFFSET('Data Element Matrix'!$B$4:$B$520, 0, ROW() - 2), "✓") | H4: 6
A5: UC04 | B5: {=_xlfn.TEXTAFTER(CELL("filename", 'UC04 Content Syndication Form S'!$A$1), "]")} | C5: Content Syndication | D5: Non-Hand Raiser | E5: Content Syndication | F5: Form Submit | G5: =COUNTIF(OFFSET('Data Element Matrix'!$B$4:$B$520, 0, ROW() - 2), "✓") | H5: 6
A6: UC05 | B6: {=_xlfn.TEXTAFTER(CELL("filename", 'UC05 1st Party Events Follow-Up'!$A$1), "]")} | C6: Manual Uploads | D6: Hand Raiser | E6: 1st Party Events | F6: Follow-Up Requested | G6: =COUNTIF(OFFSET('Data Element Matrix'!$B$4:$B$520, 0, ROW() - 2), "✓") | H6: 15
A7: UC06 | B7: {=_xlfn.TEXTAFTER(CELL("filename", 'UC06 3rd Party Events Follow-Up'!$A$1), "]")} | C7: Manual Uploads | D7: Hand Raiser | E7: 3rd Party Events | F7: Follow-Up Requested | G7: =COUNTIF(OFFSET('Data Element Matrix'!$B$4:$B$520, 0, ROW() - 2), "✓") | H7: 15
A8: UC07 | B8: {=_xlfn.TEXTAFTER(CELL("filename", 'UC07 Paid Leads Follow-Up Reque'!$A$1), "]")} | C8: Manual Uploads | D8: Hand Raiser | E8: Paid Leads | F8: Follow-Up Requested | G8: =COUNTIF(OFFSET('Data Element Matrix'!$B$4:$B$520, 0, ROW() - 2), "✓") | H8: 14
A9: UC08 | B9: {=_xlfn.TEXTAFTER(CELL("filename", 'UC08 Webinars Follow-Up Request'!$A$1), "]")} | C9: Manual Uploads | D9: Hand Raiser | E9: Webinars | F9: Follow-Up Requested | G9: =COUNTIF(OFFSET('Data Element Matrix'!$B$4:$B$520, 0, ROW() - 2), "✓") | H9: 14
A10: UC09 | B10: {=_xlfn.TEXTAFTER(CELL("filename", 'UC09 1st Party Events Attended '!$A$1), "]")} | C10: Manual Uploads | D10: Non-Hand Raiser | E10: 1st Party Events | F10: Attended Live In-Person | G10: =COUNTIF(OFFSET('Data Element Matrix'!$B$4:$B$520, 0, ROW() - 2), "✓") | H10: 17
A11: UC10 | B11: {=_xlfn.TEXTAFTER(CELL("filename", 'UC10 1st Party Events Attended '!$A$1), "]")} | C11: Manual Uploads | D11: Non-Hand Raiser | E11: 1st Party Events | F11: Attended Live Virtual | G11: =COUNTIF(OFFSET('Data Element Matrix'!$B$4:$B$520, 0, ROW() - 2), "✓") | H11: 17
A12: UC11 | B12: {=_xlfn.TEXTAFTER(CELL("filename", 'UC11 1st Party Events Attended '!$A$1), "]")} | C12: Manual Uploads | D12: Non-Hand Raiser | E12: 1st Party Events | F12: Attended Session | G12: =COUNTIF(OFFSET('Data Element Matrix'!$B$4:$B$520, 0, ROW() - 2), "✓") | H12: 18
A13: UC12 | B13: {=_xlfn.TEXTAFTER(CELL("filename", 'UC12 1st Party Events Booth Sca'!$A$1), "]")} | C13: Manual Uploads | D13: Non-Hand Raiser | E13: 1st Party Events | F13: Booth Scan | G13: =COUNTIF(OFFSET('Data Element Matrix'!$B$4:$B$520, 0, ROW() - 2), "✓") | H13: 18
A14: UC13 | B14: {=_xlfn.TEXTAFTER(CELL("filename", 'UC13 1st Party Events Registere'!$A$1), "]")} | C14: Manual Uploads | D14: Non-Hand Raiser | E14: 1st Party Events | F14: Registered | G14: =COUNTIF(OFFSET('Data Element Matrix'!$B$4:$B$520, 0, ROW() - 2), "✓") | H14: 16
A15: UC14 | B15: {=_xlfn.TEXTAFTER(CELL("filename", 'UC14 3rd Party Events Attended '!$A$1), "]")} | C15: Manual Uploads | D15: Non-Hand Raiser | E15: 3rd Party Events | F15: Attended CXO Event | G15: =COUNTIF(OFFSET('Data Element Matrix'!$B$4:$B$520, 0, ROW() - 2), "✓") | H15: 17
A16: UC15 | B16: {=_xlfn.TEXTAFTER(CELL("filename", 'UC15 3rd Party Events Attended '!$A$1), "]")} | C16: Manual Uploads | D16: Non-Hand Raiser | E16: 3rd Party Events | F16: Attended Meeting | G16: =COUNTIF(OFFSET('Data Element Matrix'!$B$4:$B$520, 0, ROW() - 2), "✓") | H16: 19
A17: UC16 | B17: {=_xlfn.TEXTAFTER(CELL("filename", 'UC16 3rd Party Events Attended '!$A$1), "]")} | C17: Manual Uploads | D17: Non-Hand Raiser | E17: 3rd Party Events | F17: Attended Session | G17: =COUNTIF(OFFSET('Data Element Matrix'!$B$4:$B$520, 0, ROW() - 2), "✓") | H17: 17
A18: UC17 | B18: {=_xlfn.TEXTAFTER(CELL("filename", 'UC17 3rd Party Events Booth Sca'!$A$1), "]")} | C18: Manual Uploads | D18: Non-Hand Raiser | E18: 3rd Party Events | F18: Booth Scan | G18: =COUNTIF(OFFSET('Data Element Matrix'!$B$4:$B$520, 0, ROW() - 2), "✓") | H18: 18
A19: UC18 | B19: {=_xlfn.TEXTAFTER(CELL("filename", 'UC18 3rd Party Events Contact R'!$A$1), "]")} | C19: Manual Uploads | D19: Non-Hand Raiser | E19: 3rd Party Events | F19: Contact Registered | G19: =COUNTIF(OFFSET('Data Element Matrix'!$B$4:$B$520, 0, ROW() - 2), "✓") | H19: 16
A20: UC19 | B20: {=_xlfn.TEXTAFTER(CELL("filename", 'UC19 Event Sponsorships Attende'!$A$1), "]")} | C20: Manual Uploads | D20: Non-Hand Raiser | E20: Event Sponsorships | F20: Attended Live In-Person | G20: =COUNTIF(OFFSET('Data Element Matrix'!$B$4:$B$520, 0, ROW() - 2), "✓") | H20: 17
A21: UC20 | B21: {=_xlfn.TEXTAFTER(CELL("filename", 'UC20 Event Sponsorships Attende'!$A$1), "]")} | C21: Manual Uploads | D21: Non-Hand Raiser | E21: Event Sponsorships | F21: Attended Session | G21: =COUNTIF(OFFSET('Data Element Matrix'!$B$4:$B$520, 0, ROW() - 2), "✓") | H21: 19
A22: UC21 | B22: {=_xlfn.TEXTAFTER(CELL("filename", 'UC21 Event Sponsorships Registe'!$A$1), "]")} | C22: Manual Uploads | D22: Non-Hand Raiser | E22: Event Sponsorships | F22: Registered | G22: =COUNTIF(OFFSET('Data Element Matrix'!$B$4:$B$520, 0, ROW() - 2), "✓") | H22: 16
A23: UC22 | B23: {=_xlfn.TEXTAFTER(CELL("filename", 'UC22 Webinars Attended Live Vir'!$A$1), "]")} | C23: Manual Uploads | D23: Non-Hand Raiser | E23: Webinars | F23: Attended Live Virtual | G23: =COUNTIF(OFFSET('Data Element Matrix'!$B$4:$B$520, 0, ROW() - 2), "✓") | H23: 19
A24: UC23 | B24: {=_xlfn.TEXTAFTER(CELL("filename", 'UC23 Webinars Attended On-Deman'!$A$1), "]")} | C24: Manual Uploads | D24: Non-Hand Raiser | E24: Webinars | F24: Attended On-Demand | G24: =COUNTIF(OFFSET('Data Element Matrix'!$B$4:$B$520, 0, ROW() - 2), "✓") | H24: 18
A25: UC24 | B25: {=_xlfn.TEXTAFTER(CELL("filename", 'UC24 Webinars Registered'!$A$1), "]")} | C25: Manual Uploads | D25: Non-Hand Raiser | E25: Webinars | F25: Registered | G25: =COUNTIF(OFFSET('Data Element Matrix'!$B$4:$B$520, 0, ROW() - 2), "✓") | H25: 15
A26: UC25 | B26: {=_xlfn.TEXTAFTER(CELL("filename", 'UC25 Offers - Contact Us Form S'!$A$1), "]")} | C26: Online Forms | D26: Hand Raiser | E26: Offers - Contact Us | F26: Form Submit | G26: =COUNTIF(OFFSET('Data Element Matrix'!$B$4:$B$520, 0, ROW() - 2), "✓") | H26: 6
A27: UC26 | B27: {=_xlfn.TEXTAFTER(CELL("filename", 'UC26 Offers - Demo Form Submit'!$A$1), "]")} | C27: Online Forms | D27: Hand Raiser | E27: Offers - Demo | F27: Form Submit | G27: =COUNTIF(OFFSET('Data Element Matrix'!$B$4:$B$520, 0, ROW() - 2), "✓") | H27: 5
A28: UC27 | B28: {=_xlfn.TEXTAFTER(CELL("filename", 'UC27 Offers - Offer Form Submit'!$A$1), "]")} | C28: Online Forms | D28: Hand Raiser | E28: Offers - Offer | F28: Form Submit | G28: =COUNTIF(OFFSET('Data Element Matrix'!$B$4:$B$520, 0, ROW() - 2), "✓") | H28: 0
A29: UC28 | B29: {=_xlfn.TEXTAFTER(CELL("filename", 'UC28 Offers - Other Form Submit'!$A$1), "]")} | C29: Online Forms | D29: Hand Raiser | E29: Offers - Other | F29: Form Submit | G29: =COUNTIF(OFFSET('Data Element Matrix'!$B$4:$B$520, 0, ROW() - 2), "✓") | H29: 1
A30: UC29 | B30: {=_xlfn.TEXTAFTER(CELL("filename", 'UC29 Offers - Others Form Submi'!$A$1), "]")} | C30: Online Forms | D30: Hand Raiser | E30: Offers - Others | F30: Form Submit | G30: =COUNTIF(OFFSET('Data Element Matrix'!$B$4:$B$520, 0, ROW() - 2), "✓") | H30: 4
A31: UC30 | B31: {=_xlfn.TEXTAFTER(CELL("filename", 'UC30 Offers - Promotion Form Su'!$A$1), "]")} | C31: Online Forms | D31: Hand Raiser | E31: Offers - Promotion | F31: Form Submit | G31: =COUNTIF(OFFSET('Data Element Matrix'!$B$4:$B$520, 0, ROW() - 2), "✓") | H31: 5
A32: UC31 | B32: {=_xlfn.TEXTAFTER(CELL("filename", 'UC31 Offers - Trial Form Submit'!$A$1), "]")} | C32: Online Forms | D32: Hand Raiser | E32: Offers - Trial | F32: Form Submit | G32: =COUNTIF(OFFSET('Data Element Matrix'!$B$4:$B$520, 0, ROW() - 2), "✓") | H32: 4
A33: UC32 | B33: {=_xlfn.TEXTAFTER(CELL("filename", 'UC32 Offers - Trials Form Submi'!$A$1), "]")} | C33: Online Forms | D33: Hand Raiser | E33: Offers - Trials | F33: Form Submit | G33: =COUNTIF(OFFSET('Data Element Matrix'!$B$4:$B$520, 0, ROW() - 2), "✓") | H33: 1

Sheet UC01 Content Syndication Attend
A1: UC01 — Content Syndication | Hand Raiser | Content Syndication | Attended on Demand
A2: ← Use Case Index | Q2: Data Element Matrix →
A3: Process | B3: Content Syndication
A4: Lead Category | B4: Hand Raiser
A5: Use Case | B5: Content Syndication
A6: Activity Type | B6: Attended on Demand
A7: Data Element | B7: Display Status | C7: Why We Need This | D7: How It Is Captured (Value Source) | E7: Data Rules | F7: Business-Friendly Prompt | G7: Input Type | H7: Outstanding Questions | I7: Attribution | J7: Operational Reporting | K7: Lead Scoring | L7: Seller Enablement | M7: Amanda Reviewed | N7: Kim Comments | O7: Stephanie Comments | P7: Briana Comments | Q7: Review Status
A8: 1 - System Classification
A9: Activity Type | B9: Required | C9: To be able to align to lead scoring and attribution models | D9: Tray.io derived | E9: Set by Tray.io on receipt of submission from Integrate. | F9: What is the Activity we are aligning attribution to? | G9: Text | I9: Yes | J9: Yes | K9: Yes | M9: Yes
A10: Use Case | B10: Derived | C10: Separated the type of Content Syndication for Attribution models to score separately | D10: Integrate Defined | E10: Set by Integrate | F10: What type of Content Syndication is this? | G10: Picklist/Text | I10: Yes | J10: Yes | K10: Yes | M10: Yes
A11: Lead Category | B11: Derived | C11: Controls funnel treatment and reporting categories. | D11: Tray.io derived | E11: Derived from selected use case, activity type, and business rules. | F11: N/A - classified by system | G11: Text | J11: Yes | L11: Yes | M11: Yes
A12: Sales Routing Trigger
A13: 2 - Contact Identity
A14: Person Party ID | B14: Derived | C14: Provides a durable contact identifier for deduplication, matching, and downstream integrations. | D14: Tray.io / Contact Database derived | E14: Tray.io appends the unique contact Person Party ID after contact matching or creation. | F14: N/A - appended by Tray.io after upload | G14: System lookup | J14: Yes | L14: Yes | M14: Yes
A15: UUID | B15: Derived | C15: Provides a durable contact identifier for deduplication, matching, and downstream integrations. | D15: Tray.io / Contact Database derived | E15: Tray.io appends the unique contact UUID after contact matching or creation. | F15: N/A - appended by Tray.io after upload | G15: System lookup | J15: Yes | L15: Yes | M15: Yes
A16: Marketing Automation Tool Contact ID | B16: Derived | C16: Provides the system contact identifier for Eloqua processing, matching, and auditability. | D16: Tray.io / Contact Database derived | E16: Tray.io appends the Marketing Automation ID after contact matching or creation. | F16: N/A - appended by Tray.io after upload | G16: System lookup | M16: Yes
A17: First Name | B17: Recommended | C17: Supports contact creation/update and personalization. | D17: Customer Input | E17: Provided by Integrate and enriched by Contact Database | F17: What is the contact first name? | G17: Text | L17: Yes | M17: Yes
A18: Last Name | B18: Required | C18: Supports contact creation/update and personalization. | D18: Customer Input | E18: Provided by Integrate and enriched by Contact Database | F18: What is the contact last name? | G18: Text | L18: Yes | M18: Yes
A19: Job Title | B19: Recommended | C19: Supports persona reporting | D19: Customer Input | E19: Provided by Integrate when available and used to derive Job Level & Department | F19: What is the contact job title? | G19: Text | L19: Yes | M19: Yes
A20: Job Level | B20: Derived | C20: Supports contact matching, enrichment, routing, and lead scoring | D20: Tray.io / Contact Database derived | E20: Tray.io appends from Contact Database or derived from Job Title when available. | F20: N/A - appended by Tray.io after upload | G20: System lookup | K20: Yes | L20: Yes | M20: Yes
A21: Job Department | B21: Derived | C21: Supports contact matching, enrichment, routing, and lead scoring | D21: Tray.io / Contact Database derived | E21: Tray.io appends from Contact Database or derived from Job Title when available. | F21: N/A - appended by Tray.io after upload | G21: System lookup | K21: Yes | L21: Yes | M21: Yes
A22: Email | B22: Required | C22: Primary contact matching key for Eloqua/SFDC and deduplication. | D22: Customer Input | E22: Provided by Integrate | F22: What is the contact email address? | G22: Email | H22: Confirm whether business email is mandatory and personal email domains are allowed. | J22: Yes | L22: Yes | M22: Yes
A23: Email Status | B23: Derived | C23: Supports email deliverability, consent, and follow-up eligibility checks. | D23: Tray.io / Contact Database derived | E23: Tray.io appends current email status from Contact Database when available. | F23: N/A - appended by Tray.io after upload | G23: System lookup | L23: Yes | M23: Yes
A24: OK to Email | B24: Derived | C24: Supports compliant email follow-up and nurture eligibility decisions. | D24: Tray.io / Contact Database derived | E24: Tray.io appends or derives the current email permission from Contact Database consent records. | F24: N/A - appended by Tray.io after upload | G24: System lookup | L24: Yes | M24: Yes
A25: Phone Status | B25: Derived | C25: Supports phone follow-up eligibility and regional compliance handling. | D25: Tray.io / Contact Database derived | E25: Tray.io appends current phone status from Contact Database when available. | F25: N/A - appended by Tray.io after upload | G25: System lookup | L25: Yes | M25: Yes
A26: OK to Call | B26: Derived | C26: Supports compliant phone follow-up and routing decisions. | D26: Tray.io / Contact Database derived | E26: Tray.io appends or derives the current call permission from Contact Database consent records. | F26: N/A - appended by Tray.io after upload | G26: System lookup | L26: Yes | M26: Yes
A27: Partner Flag | B27: Derived | C27: Identifies partner-related contacts for routing, segmentation, and reporting. | D27: Tray.io / Contact Database derived | E27: Tray.io appends from Contact Database or partner/account enrichment when available. | F27: N/A - appended by Tray.io after upload | G27: System lookup | L27: Yes | M27: Yes
A28: Student Flag | B28: Derived | C28: Identifies student contacts for segmentation, routing, and reporting. | D28: Tray.io / Contact Database derived | E28: Tray.io appends from Contact Database or derived contact profile attributes when available. | F28: N/A - appended by Tray.io after upload | G28: System lookup | L28: Yes | M28: Yes
A29: Decision Maker Type | B29: Derived | C29: Supports persona segmentation, routing, and sales prioritization. | D29: Tray.io / Contact Database derived | E29: Tray.io appends from Contact Database or derived contact profile attributes when available. | F29: N/A - appended by Tray.io after upload | G29: System lookup | J29: Yes | K29: Yes | M29: Yes
A30: Company Name | B30: Required | C30: Supports account matching, attribution, and funnel reporting. | D30: Customer Input | E30: Provided in uploaded contact file and enriched by Contact Database | F30: What company is the contact associated with? | G30: Text | H30: Confirm whether account matching requires domain, account ID, or company name only. | J30: Yes | L30: Yes | M30: Yes
A31: Region
A32: 3 - Account Identity
A33: CR Party ID | B33: Derived | C33: Provides party-level account matching support for deduplication and downstream integrations. | D33: Tray.io / Contact Database derived | E33: Tray.io appends from account or party matching enrichment when available. | F33: N/A - appended by Tray.io after upload | G33: System lookup | I33: Yes | J33: Yes | M33: Yes
A34: ORG Party ID | B34: Derived | C34: Provides organization-level account matching support for deduplication and downstream integrations. | D34: Tray.io / Contact Database derived | E34: Tray.io appends from account or organization party matching enrichment when available. | F34: N/A - appended by Tray.io after upload | G34: System lookup | I34: Yes | J34: Yes | L34: Yes | M34: Yes
A35: Address Line 1 | B35: Optional | C35: Supports account/contact matching and regional routing | D35: Integrate input/Enriched by Contact Database | E35: Adding this field will give a better account match rate in Contact Database, but will be enriched from Contact Database if known | F35: What is the contact street address? | G35: Text | L35: Yes | M35: Yes
A36: City | B36: Recommended | C36: Supports account/contact matching and regional routing | D36: Integrate input/Enriched by Contact Database | E36: Adding this field will give a better account match rate in Contact Database, but will be enriched from Contact Database if known | F36: What is the contact city? | G36: Text | L36: Yes | M36: Yes
A37: State/County | B37: Recommended | C37: Supports account/contact matching and regional routing | D37: Integrate input/Enriched by Contact Database | E37: Adding this field will give a better account match rate in Contact Database, but will be enriched from Contact Database if known | F37: What is the contact state or county? | G37: Text | L37: Yes | M37: Yes
A38: Postal/Zip Code | B38: Optional | C38: Supports account/contact matching and regional routing | D38: Integrate input/Enriched by Contact Database | E38: Adding this field will give a better account match rate in Contact Database, but will be enriched from Contact Database if known | F38: What is the contact postal or zip code? | G38: Text | L38: Yes | M38: Yes
A39: Country | B39: Required | C39: Supports routing, privacy/compliance handling, and regional reporting. | D39: Integrate Input | E39: Provided by Integrate when available. | F39: Where is the contact located? | G39: Picklist/Text | I39: Yes | J39: Yes | K39: Yes | L39: Yes | M39: Yes
A40: Named Account Flag | B40: Derived | C40: Identifies named accounts for segmentation, routing, and reporting. | D40: Tray.io / Contact Database derived | E40: Tray.io appends from account enrichment when available. | F40: N/A - appended by Tray.io after upload | G40: System lookup | J40: Yes | K40: Yes | L40: Yes | M40: Yes
...

Sheet UC02 Content Syndication Form S
A1: UC02 — Content Syndication | Hand Raiser | Content Syndication | Form Submit
A2: ← Use Case Index | Q2: Data Element Matrix →
A3: Process | B3: Content Syndication
A4: Lead Category | B4: Hand Raiser
A5: Use Case | B5: Content Syndication
A6: Activity Type | B6: Form Submit
A7: Data Element | B7: Display Status | C7: Why We Need This | D7: How It Is Captured (Value Source) | E7: Data Rules | F7: Business-Friendly Prompt | G7: Input Type | H7: Outstanding Questions | I7: Attribution | J7: Operational Reporting | K7: Lead Scoring | L7: Seller Enablement | M7: Amanda Reviewed | N7: Kim Comments | O7: Stephanie Comments | P7: Briana Comments | Q7: Review Status
A8: 1 - System Classification
A9: Activity Type | B9: Required | C9: To be able to align to lead scoring and attribution models | D9: Tray.io derived | E9: Set by Tray.io on receipt of submission from Integrate. | F9: What is the Activity we are aligning attribution to? | G9: Text | I9: Yes | J9: Yes | K9: Yes | M9: Yes
A10: Use Case | B10: Derived | C10: Separated the type of Content Syndication for Attribution models to score separately | D10: Integrate Defined | E10: Set by Integrate | F10: What type of Content Syndication is this? | G10: Picklist/Text | I10: Yes | J10: Yes | K10: Yes | M10: Yes
A11: Lead Category | B11: Derived | C11: Controls funnel treatment and reporting categories. | D11: Tray.io derived | E11: Derived from selected use case, activity type, and business rules. | F11: N/A - classified by system | G11: Text | J11: Yes | L11: Yes | M11: Yes
A12: Sales Routing Trigger
A13: 2 - Contact Identity
A14: Person Party ID | B14: Derived | C14: Provides a durable contact identifier for deduplication, matching, and downstream integrations. | D14: Tray.io / Contact Database derived | E14: Tray.io appends the unique contact Person Party ID after contact matching or creation. | F14: N/A - appended by Tray.io after upload | G14: System lookup | J14: Yes | L14: Yes | M14: Yes
A15: UUID | B15: Derived | C15: Provides a durable contact identifier for deduplication, matching, and downstream integrations. | D15: Tray.io / Contact Database derived | E15: Tray.io appends the unique contact UUID after contact matching or creation. | F15: N/A - appended by Tray.io after upload | G15: System lookup | J15: Yes | L15: Yes | M15: Yes
A16: Marketing Automation Tool Contact ID | B16: Derived | C16: Provides the system contact identifier for Eloqua processing, matching, and auditability. | D16: Tray.io / Contact Database derived | E16: Tray.io appends the Marketing Automation ID after contact matching or creation. | F16: N/A - appended by Tray.io after upload | G16: System lookup | M16: Yes
A17: First Name | B17: Recommended | C17: Supports contact creation/update and personalization. | D17: Customer Input | E17: Provided by Integrate and enriched by Contact Database | F17: What is the contact first name? | G17: Text | L17: Yes | M17: Yes
A18: Last Name | B18: Required | C18: Supports contact creation/update and personalization. | D18: Customer Input | E18: Provided by Integrate and enriched by Contact Database | F18: What is the contact last name? | G18: Text | L18: Yes | M18: Yes
A19: Job Title | B19: Recommended | C19: Supports persona reporting | D19: Customer Input | E19: Provided by Integrate when available and used to derive Job Level & Department | F19: What is the contact job title? | G19: Text | L19: Yes | M19: Yes
A20: Job Level | B20: Derived | C20: Supports contact matching, enrichment, routing, and lead scoring | D20: Tray.io / Contact Database derived | E20: Tray.io appends from Contact Database or derived from Job Title when available. | F20: N/A - appended by Tray.io after upload | G20: System lookup | K20: Yes | L20: Yes | M20: Yes
A21: Job Department | B21: Derived | C21: Supports contact matching, enrichment, routing, and lead scoring | D21: Tray.io / Contact Database derived | E21: Tray.io appends from Contact Database or derived from Job Title when available. | F21: N/A - appended by Tray.io after upload | G21: System lookup | K21: Yes | L21: Yes | M21: Yes
A22: Email | B22: Required | C22: Primary contact matching key for Eloqua/SFDC and deduplication. | D22: Customer Input | E22: Provided by Integrate | F22: What is the contact email address? | G22: Email | H22: Confirm whether business email is mandatory and personal email domains are allowed. | J22: Yes | L22: Yes | M22: Yes
A23: Email Status | B23: Derived | C23: Supports email deliverability, consent, and follow-up eligibility checks. | D23: Tray.io / Contact Database derived | E23: Tray.io appends current email status from Contact Database when available. | F23: N/A - appended by Tray.io after upload | G23: System lookup | L23: Yes | M23: Yes
A24: OK to Email | B24: Derived | C24: Supports compliant email follow-up and nurture eligibility decisions. | D24: Tray.io / Contact Database derived | E24: Tray.io appends or derives the current email permission from Contact Database consent records. | F24: N/A - appended by Tray.io after upload | G24: System lookup | L24: Yes | M24: Yes
A25: Phone Status | B25: Derived | C25: Supports phone follow-up eligibility and regional compliance handling. | D25: Tray.io / Contact Database derived | E25: Tray.io appends current phone status from Contact Database when available. | F25: N/A - appended by Tray.io after upload | G25: System lookup | L25: Yes | M25: Yes
A26: OK to Call | B26: Derived | C26: Supports compliant phone follow-up and routing decisions. | D26: Tray.io / Contact Database derived | E26: Tray.io appends or derives the current call permission from Contact Database consent records. | F26: N/A - appended by Tray.io after upload | G26: System lookup | L26: Yes | M26: Yes
A27: Partner Flag | B27: Derived | C27: Identifies partner-related contacts for routing, segmentation, and reporting. | D27: Tray.io / Contact Database derived | E27: Tray.io appends from Contact Database or partner/account enrichment when available. | F27: N/A - appended by Tray.io after upload | G27: System lookup | L27: Yes | M27: Yes
A28: Student Flag | B28: Derived | C28: Identifies student contacts for segmentation, routing, and reporting. | D28: Tray.io / Contact Database derived | E28: Tray.io appends from Contact Database or derived contact profile attributes when available. | F28: N/A - appended by Tray.io after upload | G28: System lookup | L28: Yes | M28: Yes
A29: Decision Maker Type | B29: Derived | C29: Supports persona segmentation, routing, and sales prioritization. | D29: Tray.io / Contact Database derived | E29: Tray.io appends from Contact Database or derived contact profile attributes when available. | F29: N/A - appended by Tray.io after upload | G29: System lookup | J29: Yes | K29: Yes | M29: Yes
A30: Company Name | B30: Required | C30: Supports account matching, attribution, and funnel reporting. | D30: Customer Input | E30: Provided in uploaded contact file and enriched by Contact Database | F30: What company is the contact associated with? | G30: Text | H30: Confirm whether account matching requires domain, account ID, or company name only. | J30: Yes | L30: Yes | M30: Yes
A31: Region
A32: 3 - Account Identity
A33: CR Party ID | B33: Derived | C33: Provides party-level account matching support for deduplication and downstream integrations. | D33: Tray.io / Contact Database derived | E33: Tray.io appends from account or party matching enrichment when available. | F33: N/A - appended by Tray.io after upload | G33: System lookup | I33: Yes | J33: Yes | M33: Yes
A34: ORG Party ID | B34: Derived | C34: Provides organization-level account matching support for deduplication and downstream integrations. | D34: Tray.io / Contact Database derived | E34: Tray.io appends from account or organization party matching enrichment when available. | F34: N/A - appended by Tray.io after upload | G34: System lookup | I34: Yes | J34: Yes | L34: Yes | M34: Yes
A35: Address Line 1 | B35: Optional | C35: Supports account/contact matching and regional routing | D35: Integrate input/Enriched by Contact Database | E35: Adding this field will give a better account match rate in Contact Database, but will be enriched from Contact Database if known | F35: What is the contact street address? | G35: Text | L35: Yes | M35: Yes
A36: City | B36: Recommended | C36: Supports account/contact matching and regional routing | D36: Integrate input/Enriched by Contact Database | E36: Adding this field will give a better account match rate in Contact Database, but will be enriched from Contact Database if known | F36: What is the contact city? | G36: Text | L36: Yes | M36: Yes
A37: State/County | B37: Recommended | C37: Supports account/contact matching and regional routing | D37: Integrate input/Enriched by Contact Database | E37: Adding this field will give a better account match rate in Contact Database, but will be enriched from Contact Database if known | F37: What is the contact state or county? | G37: Text | L37: Yes | M37: Yes
A38: Postal/Zip Code | B38: Optional | C38: Supports account/contact matching and regional routing | D38: Integrate input/Enriched by Contact Database | E38: Adding this field will give a better account match rate in Contact Database, but will be enriched from Contact Database if known | F38: What is the contact postal or zip code? | G38: Text | L38: Yes | M38: Yes
A39: Country | B39: Required | C39: Supports routing, privacy/compliance handling, and regional reporting. | D39: Integrate Input | E39: Provided by Integrate when available. | F39: Where is the contact located? | G39: Picklist/Text | I39: Yes | J39: Yes | K39: Yes | L39: Yes | M39: Yes
A40: Named Account Flag | B40: Derived | C40: Identifies named accounts for segmentation, routing, and reporting. | D40: Tray.io / Contact Database derived | E40: Tray.io appends from account enrichment when available. | F40: N/A - appended by Tray.io after upload | G40: System lookup | J40: Yes | K40: Yes | L40: Yes | M40: Yes
...

Sheet UC03 Content Syndication Attend
A1: UC03 — Content Syndication | Non-Hand Raiser | Content Syndication | Attended on Demand
A2: ← Use Case Index | Q2: Data Element Matrix →
A3: Process | B3: Content Syndication
A4: Lead Category | B4: Non-Hand Raiser
A5: Use Case | B5: Content Syndication
A6: Activity Type | B6: Attended on Demand
A7: Data Element | B7: Display Status | C7: Why We Need This | D7: How It Is Captured (Value Source) | E7: Data Rules | F7: Business-Friendly Prompt | G7: Input Type | H7: Outstanding Questions | I7: Attribution | J7: Operational Reporting | K7: Lead Scoring | L7: Seller Enablement | M7: Amanda Reviewed | N7: Kim Comments | O7: Stephanie Comments | P7: Briana Comments | Q7: Review Status
A8: 1 - System Classification
A9: Activity Type | B9: Required | C9: To be able to align to lead scoring and attribution models | D9: Tray.io derived | E9: Set by Tray.io on receipt of submission from Integrate. | F9: What is the Activity we are aligning attribution to? | G9: Text | I9: Yes | J9: Yes | K9: Yes | M9: Yes
A10: Use Case | B10: Derived | C10: Separated the type of Content Syndication for Attribution models to score separately | D10: Integrate Defined | E10: Set by Integrate | F10: What type of Content Syndication is this? | G10: Picklist/Text | I10: Yes | J10: Yes | K10: Yes | M10: Yes
A11: Lead Category | B11: Derived | C11: Controls funnel treatment and reporting categories. | D11: Tray.io derived | E11: Derived from selected use case, activity type, and business rules. | F11: N/A - classified by system | G11: Text | J11: Yes | M11: Yes
A12: Sales Routing Trigger
A13: 2 - Contact Identity
